Workbook

Sheet Assumptions
A1: WeLink Arizona BEAD Model - Assumptions
A3: NETWORK DESIGN
A4: Total BSLs (BEAD Obligation) | B4: 11346 | C4: Source: AZ BEAD award, P4+P5 combined
A5: BSLs Served by Tarana G2 Direct | B5: 6210 | C5: From map clustering analysis
A6: BSLs Served by Ketsen Mesh | B6: 5136 | C6: From map clustering analysis
A7: Check: Total BSLs | B7: =B5+B6 -> 11346 | C7: Must equal B4
A9: SITE COUNTS BY SCENARIO
A10: Current Design - Tower Sites | B10: 40 | C10: Existing WeLink AZ footprint
A11: Current Design - Tarana Sectors | B11: 80 | C11: 2 sectors/site avg
A12: Current Design - Ketsen Sectors | B12: 12 | C12: From original project plan Exec Summ
A13: Current Design - BSLs Covered | B13: 9584 | C13: 84.5% of obligation
A15: Corrected Design - Total Sites | B15: 101 | C15: Full coverage requires 101
A16: Corrected Design - Tarana G2 Sites | B16: 88 | C16: Multi-sector Tarana access
A17: Corrected Design - Ketsen Mesh Sites | B17: 13 | C17: Dense BSL cluster sites
A18: Corrected Design - Tarana G2 Access Sectors | B18: 102 | C18: 88 sites, avg ~1.16 sectors (multi-sector)
A19: Corrected Design - Tarana P2P BH Sectors | B19: 13 | C19: 1 BH sector per Ketsen site
A20: Corrected Design - Total Sectors | B20: 115 | C20: 102 access + 13 P2P BH
A21: Corrected Design - Ketsen Gateways | B21: 13 | C21: 1 per Ketsen cluster site
A23: Optimized Design - Colocation Sites | B23: 24 | C23: DA + EarthLink towers
A24: Optimized Design - New Build Sites | B24: 77 | C24: Short monopoles
A25: Optimized Design - Total Sites | B25: 101 | C25: =24+77 -> 101
A26: Optimized Design - Tarana G2 Sites | B26: 88 | C26: Same arch as Corrected
A27: Optimized Design - Ketsen Mesh Sites | B27: 13 | C27: Same arch as Corrected
A28: Optimized Design - Total Sectors | B28: 115 | C28: Same as Corrected
A29: Optimized Design - Ketsen Gateways | B29: 13 | C29: Same as Corrected
A31: BEAD AWARD
A32: BEAD Award - P4 | B32: 11039630 | C32: Source: AZ BEAD disbursement schedule
A33: BEAD Award - P5 | B33: 5024352 | C33: Source: AZ BEAD disbursement schedule
A34: Total BEAD Funding | B34: =B32+B33 -> 16063982 | C34: Formula
A35: Retainage / Holdback (%) | B35: 0.1 | C35: Assume 10% until final closeout
A36: Net BEAD Available at Draw | B36: =B34*(1-B35) -> 14457584 | C36: Total less retainage
A38: BEAD DRAW TIMING
A39: Year 1 Draw (% of net) | B39: 0.4 | C39: First 40% at milestones 5%+15%+20%
A40: Year 2 Draw (% of net) | B40: 0.3 | C40: 15%+15% milestones
A41: Year 3 Draw (% of net) | B41: 0.2 | C41: 15%+5% milestones
A42: Year 4 Draw (% of net) | B42: 0.1 | C42: Final closeout + retainage release
A43: Construction Duration (months) | B43: 30 | C43: ~2.5 years from subgrant execution
A44: Permitting Lead Time (months) | B44: 6 | C44: App, design, NEPA
A45: Contingency Months | B45: 3 | C45: Weather, supply chain, utility delays
A47: SUBSCRIBER ECONOMICS
...

Sheet Current Design
A1: WeLink AZ BEAD - Current Design (40 Sites)
A3: DESIGN SUMMARY
A4: Tower Sites | B4: 40
A5: Tarana G2 Sectors | B5: 80
A6: Ketsen Sectors | B6: 12
A7: BSLs Assigned | B7: 9584
A8: BSL Gap | B8: =Assumptions!B4-B7 -> 1762
A10: INFRASTRUCTURE CAPEX (Architecture-Driven)
A11: Sector Equipment (80 sectors) | B11: =B5*Assumptions!B69 -> 1680000 | C11: Tarana G2 sectors * $21K BN
A12: Per-Site Accessories | B12: =B4*Assumptions!B70 -> 57840 | C12: 40 sites * $1,446
A13: Ketsen Gateways (12) | B13: =B6*Assumptions!B72 -> 24000 | C13: 12 * $2,000
A14: Tower Infrastructure (assumed existing) | B14: 0 | C14: Current sites already built
A15: Make-Ready / Power | B15: =B4*Assumptions!B77 -> 400000 | C15: $10K/site
A16: Subtotal Pre-Contingency | B16: =SUM(B11:B15) -> 2161840
A17: Contingency | B17: =B16*Assumptions!B78 -> 216184
A18: Total Infrastructure CAPEX | B18: =B16+B17 -> 2378024
A20: 5-YEAR P&L PROJECTION
A21: Metric | B21: Year 1 | C21: Year 2 | D21: Year 3 | E21: Year 4 | F21: Year 5
A22: Tarana Take Rate | B22: =Assumptions!B53 -> 0.05 | C22: =Assumptions!B54 -> 0.08 | D22: =Assumptions!B55 -> 0.12 | E22: =Assumptions!B56 -> 0.16 | F22: =Assumptions!B57 -> 0.2
A23: Ketsen Take Rate | B23: =Assumptions!C53 -> 0.04 | C23: =Assumptions!C54 -> 0.07 | D23: =Assumptions!C55 -> 0.1 | E23: =Assumptions!C56 -> 0.14 | F23: =Assumptions!C57 -> 0.18
A24: Tarana Subscribers | B24: =B7*B22 -> 479.2 | C24: =B7*C22 -> 766.72 | D24: =B7*D22 -> 1150.08 | E24: =B7*E22 -> 1533.44 | F24: =B7*F22 -> 1916.8
A25: Ketsen Subscribers | B25: 0 | C25: 0 | D25: 0 | E25: 0 | F25: 0
A26: Total Subscribers | B26: =B24+B25 -> 479.2 | C26: =C24+C25 -> 766.72 | D26: =D24+D25 -> 1150.08 | E26: =E24+E25 -> 1533.44 | F26: =F24+F25 -> 1916.8
A27: Revenue | B27: =B26*Assumptions!B49 -> 402528 | C27: =C26*Assumptions!B49 -> 644044.8 | D27: =D26*Assumptions!B49 -> 966067.2 | E27: =E26*Assumptions!B49 -> 1288089.6 | F27: =F26*Assumptions!B49 -> 1610112
A29: Tarana CPE CAPEX | B29: =B24*Assumptions!B63 -> 337836 | C29: =(C24-B24)*Assumptions!B63 -> 202701.6 | D29: =(D24-C24)*Assumptions!B63 -> 270268.8 | E29: =(E24-D24)*Assumptions!B63 -> 270268.8 | F29: =(F24-E24)*Assumptions!B63 -> 270268.8
A30: Ketsen CPE CAPEX | B30: =B25*Assumptions!B66 -> 0 | C30: =(C25-B25)*Assumptions!B66 -> 0 | D30: =(D25-C25)*Assumptions!B66 -> 0 | E30: =(E25-D25)*Assumptions!B66 -> 0 | F30: =(F25-E25)*Assumptions!B66 -> 0
A31: Total CPE CAPEX | B31: =B29+B30 -> 337836 | C31: =C29+C30 -> 202701.6 | D31: =D29+D30 -> 270268.8 | E31: =E29+E30 -> 270268.8 | F31: =F29+F30 -> 270268.8
A32: Total CAPEX | B32: =B18+B31 -> 2715860 | C32: =C31 -> 202701.6 | D32: =D31 -> 270268.8 | E32: =E31 -> 270268.8 | F32: =F31 -> 270268.8
A34: OPEX DETAIL
A35: Tower / Site Leases | B35: =B4*Assumptions!B81 -> 720000 | C35: =B4*Assumptions!B81*(1+Assumptions!B92)^1 -> 741600 | D35: =B4*Assumptions!B81*(1+Assumptions!B92)^2 -> 763848 | E35: =B4*Assumptions!B81*(1+Assumptions!B92)^3 -> 786763.44 | F35: =B4*Assumptions!B81*(1+Assumptions!B92)^4 -> 810366.34
A36: Tower Power | B36: =B4*Assumptions!B83 -> 144000 | C36: =B4*Assumptions!B83*(1+Assumptions!B92)^1 -> 148320 | D36: =B4*Assumptions!B83*(1+Assumptions!B92)^2 -> 152769.6 | E36: =B4*Assumptions!B83*(1+Assumptions!B92)^3 -> 157352.69 | F36: =B4*Assumptions!B83*(1+Assumptions!B92)^4 -> 162073.27
A37: NOC / Network Ops | B37: =Assumptions!B84 -> 180000 | C37: =Assumptions!B84*(1+Assumptions!B92)^1 -> 185400 | D37: =Assumptions!B84*(1+Assumptions!B92)^2 -> 190962 | E37: =Assumptions!B84*(1+Assumptions!B92)^3 -> 196690.86 | F37: =Assumptions!B84*(1+Assumptions!B92)^4 -> 202591.59
A38: Transport / Backhaul | B38: =B4*Assumptions!B85 -> 48000 | C38: =B4*Assumptions!B85*(1+Assumptions!B92)^1 -> 49440 | D38: =B4*Assumptions!B85*(1+Assumptions!B92)^2 -> 50923.2 | E38: =B4*Assumptions!B85*(1+Assumptions!B92)^3 -> 52450.896 | F38: =B4*Assumptions!B85*(1+Assumptions!B92)^4 -> 54024.423
A39: Field Maintenance | B39: =Assumptions!B86 -> 120000 | C39: =Assumptions!B86*(1+Assumptions!B92)^1 -> 123600 | D39: =Assumptions!B86*(1+Assumptions!B92)^2 -> 127308 | E39: =Assumptions!B86*(1+Assumptions!B92)^3 -> 131127.24 | F39: =Assumptions!B86*(1+Assumptions!B92)^4 -> 135061.06
A40: Customer Support / OSS-BSS | B40: =B26*Assumptions!B87 -> 17251.2 | C40: =C26*Assumptions!B87 -> 27601.92 | D40: =D26*Assumptions!B87 -> 41402.88 | E40: =E26*Assumptions!B87 -> 55203.84 | F40: =F26*Assumptions!B87 -> 69004.8
A41: SMS Management | B41: =B24*Assumptions!B88 -> 22522.4 | C41: =C24*Assumptions!B88 -> 36035.84 | D41: =D24*Assumptions!B88 -> 54053.76 | E41: =E24*Assumptions!B88 -> 72071.68 | F41: =F24*Assumptions!B88 -> 90089.6
A42: SAS / CBRS | B42: =B24*Assumptions!B89 -> 5750.4 | C42: =C24*Assumptions!B89 -> 9200.64 | D42: =D24*Assumptions!B89 -> 13800.96 | E42: =E24*Assumptions!B89 -> 18401.28 | F42: =F24*Assumptions!B89 -> 23001.6
A43: Insurance | B43: =Assumptions!B90 -> 48000 | C43: =Assumptions!B90*(1+Assumptions!B92)^1 -> 49440 | D43: =Assumptions!B90*(1+Assumptions!B92)^2 -> 50923.2 | E43: =Assumptions!B90*(1+Assumptions!B92)^3 -> 52450.896 | F43: =Assumptions!B90*(1+Assumptions!B92)^4 -> 54024.423
A44: Spares / Warranty Reserve | B44: =B18*Assumptions!B91 -> 47560.48 | C44: =B18*Assumptions!B91 -> 47560.48 | D44: =B18*Assumptions!B91 -> 47560.48 | E44: =B18*Assumptions!B91 -> 47560.48 | F44: =B18*Assumptions!B91 -> 47560.48
A45: Total OPEX | B45: =B35+B36+B37+B38+B39+B40+B41+B42+B43+B44 -> 1353084.5 | C45: =C35+C36+C37+C38+C39+C40+C41+C42+C43+C44 -> 1418198.9 | D45: =D35+D36+D37+D38+D39+D40+D41+D42+D43+D44 -> 1493552.1 | E45: =E35+E36+E37+E38+E39+E40+E41+E42+E43+E44 -> 1570073.3 | F45: =F35+F36+F37+F38+F39+F40+F41+F42+F43+F44 -> 1647797.6
...

Sheet Corrected Design
A1: WeLink AZ BEAD - Corrected Design (101 Sites)
A3: DESIGN SUMMARY
A4: Total Sites | B4: 101
A5: Tarana G2 Sites | B5: 88
A6: Ketsen Mesh Sites | B6: 13
A7: Tarana G2 Access Sectors | B7: 102
A8: Tarana P2P BH Sectors | B8: 13
A9: Total Sectors | B9: =B7+B8 -> 115
A10: Ketsen Gateways | B10: 13
A11: BSLs Assigned (Tarana) | B11: =Assumptions!B5 -> 6210
A12: BSLs Assigned (Ketsen) | B12: =Assumptions!B6 -> 5136
A13: Total BSLs Assigned | B13: =B11+B12 -> 11346
A14: BSL Gap | B14: =Assumptions!B4-B13 -> 0
A16: INFRASTRUCTURE CAPEX (Architecture-Driven)
A17: Tarana G2 BN Equipment (102 access sectors) | B17: =B7*Assumptions!B69 -> 2142000 | C17: 102 access sectors * $21K
A18: Tarana P2P BH Radios (13 sectors) | B18: =B8*Assumptions!B71 -> 151242 | C18: 13 BH sectors * $11,634
A19: Per-Site Accessories | B19: =B4*Assumptions!B70 -> 146046 | C19: 101 sites * $1,446
A20: Ketsen Gateways | B20: =B10*Assumptions!B72 -> 26000 | C20: 13 * $2,000
A21: New Tower Build (101 sites) | B21: =B4*Assumptions!B75 -> 5050000 | C21: 101 * $50K
A22: Make-Ready / Power | B22: =B4*Assumptions!B77 -> 1010000 | C22: 101 * $10K
A23: Subtotal Pre-Contingency | B23: =SUM(B17:B22) -> 8525288
A24: Contingency | B24: =B23*Assumptions!B78 -> 852528.8
A25: Total Infrastructure CAPEX | B25: =B23+B24 -> 9377816.8
A27: 5-YEAR P&L PROJECTION
A28: Metric | B28: Year 1 | C28: Year 2 | D28: Year 3 | E28: Year 4 | F28: Year 5
A29: Tarana Take Rate | B29: =Assumptions!B53 -> 0.05 | C29: =Assumptions!B54 -> 0.08 | D29: =Assumptions!B55 -> 0.12 | E29: =Assumptions!B56 -> 0.16 | F29: =Assumptions!B57 -> 0.2
A30: Ketsen Take Rate | B30: =Assumptions!C53 -> 0.04 | C30: =Assumptions!C54 -> 0.07 | D30: =Assumptions!C55 -> 0.1 | E30: =Assumptions!C56 -> 0.14 | F30: =Assumptions!C57 -> 0.18
A31: Tarana Subscribers | B31: =B11*B29 -> 310.5 | C31: =B11*C29 -> 496.8 | D31: =B11*D29 -> 745.2 | E31: =B11*E29 -> 993.6 | F31: =B11*F29 -> 1242
A32: Ketsen Subscribers | B32: =B12*B30 -> 205.44 | C32: =B12*C30 -> 359.52 | D32: =B12*D30 -> 513.6 | E32: =B12*E30 -> 719.04 | F32: =B12*F30 -> 924.48
A33: Total Subscribers | B33: =B31+B32 -> 515.94 | C33: =C31+C32 -> 856.32 | D33: =D31+D32 -> 1258.8 | E33: =E31+E32 -> 1712.64 | F33: =F31+F32 -> 2166.48
A34: Revenue | B34: =B33*Assumptions!B49 -> 433389.6 | C34: =C33*Assumptions!B49 -> 719308.8 | D34: =D33*Assumptions!B49 -> 1057392 | E34: =E33*Assumptions!B49 -> 1438617.6 | F34: =F33*Assumptions!B49 -> 1819843.2
A36: Tarana CPE CAPEX | B36: =B31*Assumptions!B63 -> 218902.5 | C36: =(C31-B31)*Assumptions!B63 -> 131341.5 | D36: =(D31-C31)*Assumptions!B63 -> 175122 | E36: =(E31-D31)*Assumptions!B63 -> 175122 | F36: =(F31-E31)*Assumptions!B63 -> 175122
A37: Ketsen CPE CAPEX | B37: =B32*Assumptions!B66 -> 71904 | C37: =(C32-B32)*Assumptions!B66 -> 53928 | D37: =(D32-C32)*Assumptions!B66 -> 53928 | E37: =(E32-D32)*Assumptions!B66 -> 71904 | F37: =(F32-E32)*Assumptions!B66 -> 71904
A38: Total CPE CAPEX | B38: =B36+B37 -> 290806.5 | C38: =C36+C37 -> 185269.5 | D38: =D36+D37 -> 229050 | E38: =E36+E37 -> 247026 | F38: =F36+F37 -> 247026
A39: Total CAPEX | B39: =B25+B38 -> 9668623.3 | C39: =C38 -> 185269.5 | D39: =D38 -> 229050 | E39: =E38 -> 247026 | F39: =F38 -> 247026
A41: OPEX DETAIL
A42: Tower / Site Leases | B42: =B4*Assumptions!B82 -> 606000 | C42: =B4*Assumptions!B82*(1+Assumptions!B92)^1 -> 624180 | D42: =B4*Assumptions!B82*(1+Assumptions!B92)^2 -> 642905.4 | E42: =B4*Assumptions!B82*(1+Assumptions!B92)^3 -> 662192.56 | F42: =B4*Assumptions!B82*(1+Assumptions!B92)^4 -> 682058.34
A43: Tower Power | B43: =B4*Assumptions!B83 -> 363600 | C43: =B4*Assumptions!B83*(1+Assumptions!B92)^1 -> 374508 | D43: =B4*Assumptions!B83*(1+Assumptions!B92)^2 -> 385743.24 | E43: =B4*Assumptions!B83*(1+Assumptions!B92)^3 -> 397315.54 | F43: =B4*Assumptions!B83*(1+Assumptions!B92)^4 -> 409235
A44: NOC / Network Ops | B44: =Assumptions!B84 -> 180000 | C44: =Assumptions!B84*(1+Assumptions!B92)^1 -> 185400 | D44: =Assumptions!B84*(1+Assumptions!B92)^2 -> 190962 | E44: =Assumptions!B84*(1+Assumptions!B92)^3 -> 196690.86 | F44: =Assumptions!B84*(1+Assumptions!B92)^4 -> 202591.59
A45: Transport / Backhaul | B45: =B4*Assumptions!B85 -> 121200 | C45: =B4*Assumptions!B85*(1+Assumptions!B92)^1 -> 124836 | D45: =B4*Assumptions!B85*(1+Assumptions!B92)^2 -> 128581.08 | E45: =B4*Assumptions!B85*(1+Assumptions!B92)^3 -> 132438.51 | F45: =B4*Assumptions!B85*(1+Assumptions!B92)^4 -> 136411.67
...

Sheet Optimized Design
A1: WeLink AZ BEAD - Optimized Design (24 Coloc + 77 New)
A3: DESIGN SUMMARY
A4: Colocation Sites | B4: 24
A5: New Build Sites | B5: 77
A6: Total Sites | B6: =B4+B5 -> 101
A7: Tarana G2 Sites | B7: 88
A8: Ketsen Mesh Sites | B8: 13
A9: Tarana G2 Access Sectors | B9: 102
A10: Tarana P2P BH Sectors | B10: 13
A11: Total Sectors | B11: =B9+B10 -> 115
A12: Ketsen Gateways | B12: 13
A13: BSLs Assigned (Tarana) | B13: =Assumptions!B5 -> 6210
A14: BSLs Assigned (Ketsen) | B14: =Assumptions!B6 -> 5136
A15: Total BSLs Assigned | B15: =B13+B14 -> 11346
A16: BSL Gap | B16: =Assumptions!B4-B15 -> 0
A18: INFRASTRUCTURE CAPEX (Architecture-Driven)
A19: Tarana G2 BN Equipment (102 access sectors) | B19: =B9*Assumptions!B69 -> 2142000 | C19: 102 access sectors * $21K
A20: Tarana P2P BH Radios (13 sectors) | B20: =B10*Assumptions!B71 -> 151242 | C20: 13 BH sectors * $11,634
A21: Per-Site Accessories | B21: =B6*Assumptions!B70 -> 146046 | C21: 101 sites * $1,446
A22: Ketsen Gateways | B22: =B12*Assumptions!B72 -> 26000 | C22: 13 * $2,000
A23: Colocation Setup | B23: =B4*Assumptions!B76 -> 600000 | C23: 24 * $25K
A24: New Tower Build | B24: =B5*Assumptions!B75 -> 3850000 | C24: 77 * $50K
A25: Make-Ready / Power | B25: =B6*Assumptions!B77 -> 1010000 | C25: 101 * $10K
A26: Subtotal Pre-Contingency | B26: =SUM(B19:B25) -> 7925288
A27: Contingency | B27: =B26*Assumptions!B78 -> 792528.8
A28: Total Infrastructure CAPEX | B28: =B26+B27 -> 8717816.8
A30: 5-YEAR P&L PROJECTION
A31: Metric | B31: Year 1 | C31: Year 2 | D31: Year 3 | E31: Year 4 | F31: Year 5
A32: Tarana Take Rate | B32: =Assumptions!B53 -> 0.05 | C32: =Assumptions!B54 -> 0.08 | D32: =Assumptions!B55 -> 0.12 | E32: =Assumptions!B56 -> 0.16 | F32: =Assumptions!B57 -> 0.2
A33: Ketsen Take Rate | B33: =Assumptions!C53 -> 0.04 | C33: =Assumptions!C54 -> 0.07 | D33: =Assumptions!C55 -> 0.1 | E33: =Assumptions!C56 -> 0.14 | F33: =Assumptions!C57 -> 0.18
A34: Tarana Subscribers | B34: =B13*B32 -> 310.5 | C34: =B13*C32 -> 496.8 | D34: =B13*D32 -> 745.2 | E34: =B13*E32 -> 993.6 | F34: =B13*F32 -> 1242
A35: Ketsen Subscribers | B35: =B14*B33 -> 205.44 | C35: =B14*C33 -> 359.52 | D35: =B14*D33 -> 513.6 | E35: =B14*E33 -> 719.04 | F35: =B14*F33 -> 924.48
A36: Total Subscribers | B36: =B34+B35 -> 515.94 | C36: =C34+C35 -> 856.32 | D36: =D34+D35 -> 1258.8 | E36: =E34+E35 -> 1712.64 | F36: =F34+F35 -> 2166.48
A37: Revenue | B37: =B36*Assumptions!B49 -> 433389.6 | C37: =C36*Assumptions!B49 -> 719308.8 | D37: =D36*Assumptions!B49 -> 1057392 | E37: =E36*Assumptions!B49 -> 1438617.6 | F37: =F36*Assumptions!B49 -> 1819843.2
A39: Tarana CPE CAPEX | B39: =B34*Assumptions!B63 -> 218902.5 | C39: =(C34-B34)*Assumptions!B63 -> 131341.5 | D39: =(D34-C34)*Assumptions!B63 -> 175122 | E39: =(E34-D34)*Assumptions!B63 -> 175122 | F39: =(F34-E34)*Assumptions!B63 -> 175122
A40: Ketsen CPE CAPEX | B40: =B35*Assumptions!B66 -> 71904 | C40: =(C35-B35)*Assumptions!B66 -> 53928 | D40: =(D35-C35)*Assumptions!B66 -> 53928 | E40: =(E35-D35)*Assumptions!B66 -> 71904 | F40: =(F35-E35)*Assumptions!B66 -> 71904
A41: Total CPE CAPEX | B41: =B39+B40 -> 290806.5 | C41: =C39+C40 -> 185269.5 | D41: =D39+D40 -> 229050 | E41: =E39+E40 -> 247026 | F41: =F39+F40 -> 247026
A42: Total CAPEX | B42: =B28+B41 -> 9008623.3 | C42: =C41 -> 185269.5 | D42: =D41 -> 229050 | E42: =E41 -> 247026 | F42: =F41 -> 247026
A44: OPEX DETAIL
A45: Tower / Site Leases | B45: =B4*Assumptions!B81+B5*Assumptions!B82 -> 894000 | C45: =B4*Assumptions!B81+B5*Assumptions!B82*(1+Assumptions!B92)^1 -> 907860 | D45: =B4*Assumptions!B81+B5*Assumptions!B82*(1+Assumptions!B92)^2 -> 922135.8 | E45: =B4*Assumptions!B81+B5*Assumptions!B82*(1+Assumptions!B92)^3 -> 936839.87 | F45: =B4*Assumptions!B81+B5*Assumptions!B82*(1+Assumptions!B92)^4 -> 951985.07
...

Sheet Comparison
A1: WeLink AZ BEAD - Design Comparison
A3: Metric | B3: Current | C3: Corrected | D3: Optimized
A4: ARCHITECTURE
A5: Total Sites | B5: ='Current Design'!B4 -> 40 | C5: ='Corrected Design'!B4 -> 101 | D5: ='Optimized Design'!B6 -> 101
A6: Total Sectors | B6: ='Current Design'!B5 -> 80 | C6: ='Corrected Design'!B9 -> 115 | D6: ='Optimized Design'!B11 -> 115
A7: BSLs Covered | B7: ='Current Design'!B7 -> 9584 | C7: ='Corrected Design'!B13 -> 11346 | D7: ='Optimized Design'!B15 -> 11346
A8: BSL Gap | B8: ='Current Design'!B8 -> 1762 | C8: ='Corrected Design'!B14 -> 0 | D8: ='Optimized Design'!B16 -> 0
A9: BEAD Coverage % | B9: ='Current Design'!B7/Assumptions!B4 -> 0.84470298 | C9: ='Corrected Design'!B13/Assumptions!B4 -> 1 | D9: ='Optimized Design'!B15/Assumptions!B4 -> 1
A10: Colocation Sites | B10: 0 | C10: 0 | D10: ='Optimized Design'!B4 -> 24
A11: New Build Sites | B11: ='Current Design'!B4 -> 40 | C11: ='Corrected Design'!B4 -> 101 | D11: ='Optimized Design'!B5 -> 77
A12: Ketsen Cluster Sites | B12: 0 | C12: 13 | D12: 13
A13: CAPEX
A14: Infrastructure CAPEX | B14: ='Current Design'!B18 -> 2378024 | C14: ='Corrected Design'!B25 -> 9377816.8 | D14: ='Optimized Design'!B28 -> 8717816.8
A15: Year 1 Total CAPEX | B15: ='Current Design'!B32 -> 2715860 | C15: ='Corrected Design'!B39 -> 9668623.3 | D15: ='Optimized Design'!B42 -> 9008623.3
A16: 5-Year Total CAPEX | B16: =SUM('Current Design'!B32:F32) -> 3729368 | C16: =SUM('Corrected Design'!B39:F39) -> 10576995 | D16: =SUM('Optimized Design'!B42:F42) -> 9916994.8
A17: FINANCIAL
A18: Year 5 Revenue | B18: ='Current Design'!F27 -> 1610112 | C18: ='Corrected Design'!F34 -> 1819843.2 | D18: ='Optimized Design'!F37 -> 1819843.2
A19: Year 5 EBITDA | B19: ='Current Design'!F47 -> -37685.581 | C19: ='Corrected Design'!F54 -> -138366.49 | D19: ='Optimized Design'!F57 -> -395093.22
A20: Year 5 EBITDA Margin | B20: ='Current Design'!F48 -> -0.023405565 | C20: ='Corrected Design'!F55 -> -0.076032095 | D20: ='Optimized Design'!F58 -> -0.21710289
A21: 5-Year Cumulative FCF | B21: ='Current Design'!F53 -> 9762749.3 | C21: ='Corrected Design'!F60 -> 1921107.7 | D21: ='Optimized Design'!F63 -> 1251623.3
A22: Year 5 Total Subscribers | B22: ='Current Design'!F26 -> 1916.8 | C22: ='Corrected Design'!F33 -> 2166.48 | D22: ='Optimized Design'!F36 -> 2166.48

Sheet Reconciliation
A1: Model-to-Map Reconciliation
A3: Item | B3: Current | C3: Corrected | D3: Optimized | E3: Map Value | F3: Status
A4: Total BSLs (Obligation) | B4: =Assumptions!B4 -> 11346 | C4: =Assumptions!B4 -> 11346 | D4: =Assumptions!B4 -> 11346 | E4: 11,346 | F4: Match
A5: BSLs Covered | B5: ='Current Design'!B7 -> 9584 | C5: ='Corrected Design'!B13 -> 11346 | D5: ='Optimized Design'!B15 -> 11346 | E5: 9,584 / 11,346 / 11,346 | F5: Verify map KPIs
A6: Tower / Site Count | B6: ='Current Design'!B4 -> 40 | C6: ='Corrected Design'!B4 -> 101 | D6: ='Optimized Design'!B6 -> 101 | E6: 40 / 101 / 101 | F6: Verify map KPIs
A7: Total Sectors | B7: ='Current Design'!B5 -> 80 | C7: ='Corrected Design'!B9 -> 115 | D7: ='Optimized Design'!B11 -> 115 | E7: 80 / 115 / 115 | F7: Verify map KPIs
A8: Ketsen Cluster Sites | B8: 0 | C8: 13 | D8: 13 | E8: 12 / 13 / 13 | F8: Current tab shows 12 in map
A9: Tarana G2 Access Sectors | B9: 80 | C9: 102 | D9: 102 | E9: Not shown | F9: Map shows total sectors only
A10: Tarana P2P BH Sectors | B10: 0 | C10: 13 | D10: 13 | E10: Not shown | F10: Map shows total sectors only
A11: BSLs Served by Tarana | B11: 9,584 | C11: ='Corrected Design'!B11 -> 6210 | D11: ='Optimized Design'!B13 -> 6210 | E11: 6,210 | F11: Verify split matches map layers
A12: BSLs Served by Ketsen | B12: 0 | C12: ='Corrected Design'!B12 -> 5136 | D12: ='Optimized Design'!B14 -> 5136 | E12: 5,136 | F12: Verify split matches map layers
A13: Infra CAPEX | B13: ='Current Design'!B18 -> 2378024 | C13: ='Corrected Design'!B25 -> 9377816.8 | D13: ='Optimized Design'!B28 -> 8717816.8 | E13: Hardcoded in map | F13: Map must read from model
A14: Colocation Sites | B14: 0 | C14: 0 | D14: ='Optimized Design'!B4 -> 24 | E14: 24 | F14: Match
A15: New Build Sites | B15: ='Current Design'!B4 -> 40 | C15: ='Corrected Design'!B4 -> 101 | D15: ='Optimized Design'!B5 -> 77 | E15: 77 | F15: Optimized only

Sheet Sensitivity
A1: Scenario & Sensitivity Analysis
A2: Based on Optimized Design (24 Coloc + 77 New Build)
A4: STEADY-STATE PENETRATION SENSITIVITY (Year 5)
A5: Metric | B5: 25% | C5: 30% | D5: 35%
A6: Penetration Rate | B6: 0.25 | C6: 0.3 | D6: 0.35
A7: Total Subscribers | B7: =Assumptions!B4*B6 -> 2836.5 | C7: =Assumptions!B4*C6 -> 3403.8 | D7: =Assumptions!B4*D6 -> 3971.1
A8: Annual Revenue | B8: =B7*Assumptions!B49 -> 2382660 | C8: =C7*Assumptions!B49 -> 2859192 | D8: =D7*Assumptions!B49 -> 3335724
A9: Annual OPEX (est from Opt Y5) | B9: ='Optimized Design'!F55 -> 2214936.4 | C9: ='Optimized Design'!F55 -> 2214936.4 | D9: ='Optimized Design'!F55 -> 2214936.4
A10: Steady-State EBITDA | B10: =B6-B9 -> -2214936.2 | C10: =C6-C9 -> -2214936.1 | D10: =D6-D9 -> -2214936.1
A11: Steady-State EBITDA Margin | B11: =IF(B6=0,0,B10/B6) -> -8859744.7 | C11: =IF(C6=0,0,C10/C6) -> -7383120.4 | D11: =IF(D6=0,0,D10/D6) -> -6328388.8
A14: SCENARIO ANALYSIS
A15: Assumption | B15: Downside | C15: Base | D15: Upside
A16: Year 5 Tarana Take Rate | B16: 0.15 | C16: 0.2 | D16: 0.25
A17: Year 5 Ketsen Take Rate | B17: 0.12 | C17: 0.18 | D17: 0.22
A18: Monthly ARPU | B18: 65 | C18: 70 | D18: 75
A19: New Tower Build Cost | B19: 60000 | C19: 50000 | D19: 45000
A20: Construction Overrun (%) | B20: 0.2 | C20: 0.1 | D20: 0.05
A21: BEAD Draw Delay (months) | B21: 6 | C21: 0 | D21: 0
A22: Annual OPEX Escalator | B22: 0.04 | C22: 0.03 | D22: 0.02
A24: NOTE: Scenario impacts are directional. Full scenario P&L
A25: requires separate scenario tabs or a scenario toggle in Assumptions.
A26: The sensitivity table above shows steady-state economics.

Sheet Issues Found
A1: Audit Issues Found
A3: # | B3: Issue | C3: Why It Matters | D3: Fix Applied
A4: 1 | B4: Comparison sheet references broken | C4: Row insertions for Ketsen data shifted cell refs. Corrected BSLs showed 13 instead of 11,346. Optimized CAPEX showed $600K (coloc only). All downstream Comparison values wrong. | D4: Rebuilt Comparison with correct cross-sheet refs to new row layout.
A5: 2 | B5: Sector equipment CAPEX never used | C5: Assumptions had $50K/sector for Tarana G2 BN but no scenario formula used it. Infrastructure CAPEX was either hardcoded or only counted tower build costs. Understated CAPEX by $2-3M. | D5: Replaced with architecture-driven CAPEX: G2 BN at $21K/sector + $11,634/P2P BH sector + per-site accessories, all formula-linked.
A6: 3 | B6: Corrected Design Infra CAPEX hardcoded | C6: $5,076,000 hardcoded with no formula decomposition. Cannot audit, cannot sensitivity-test, cannot tie to architecture. | D6: Replaced with formula: sectors*BN + P2P*BH + sites*accessories + gateways + tower build + make-ready + contingency.
A7: 4 | B7: Current Design Infra CAPEX hardcoded | C7: $3,260,000 with no formula basis. Board/lender cannot verify. | D7: Replaced with formula-driven CAPEX built from sector count, per-site accessories, make-ready.
A8: 5 | B8: OPEX was 10% of revenue | C8: Completely unrealistic. At 5% take rate in Y1, total OPEX would be ~$40K while tower leases alone are $720K+. Understated early-year OPEX by 10-20x, overstated EBITDA. | D8: Replaced with 10-line itemized OPEX: leases, power, NOC, transport, field maintenance, customer support, SMS, SAS, insurance, spares. Each linked to Assumptions.
A9: 6 | B9: Tower leases wrong for Corrected Design | C9: All 101 sites used New Tower Lease ($24K/yr). Should differentiate coloc vs new build. Overstated Corrected lease expense. | D9: Corrected: all new build at $6K ground lease. Optimized: split 24 coloc at $18K + 77 new at $6K.
A10: 7 | B10: No BEAD draw timing or retainage | C10: Model assumed full P4 in Y1, full P5 in Y2. Real BEAD has milestone-based draws and 10% retainage until closeout. Overstated early cash position. | D10: Added retainage assumption (10%), draw timing schedule (40/30/20/10%), retainage release in Y4.
A11: 8 | B11: No contingency in CAPEX | C11: Zero contingency on a 101-site new build across Maricopa County. No buffer for permitting, weather, supply chain. Not defensible for board or state review. | D11: Added 10% contingency on pre-contingency infrastructure CAPEX.
A12: 9 | B12: CPE cost not split by technology | C12: Uniform $705/sub CPE for all BSLs. Ketsen mesh CPE is likely cheaper than Tarana G2 RN. | D12: Split CPE: Tarana at $705 (RNv $455 + BW $100 + Install $150), Ketsen at $350 ($250 + $100).
A13: 10 | B13: No technology-segmented take rates | C13: One take rate for all BSLs regardless of architecture. Dense Ketsen areas may have different adoption curves. | D13: Added separate Tarana and Ketsen take rate columns in Assumptions. Ketsen rates slightly lower to reflect density/competition dynamics.
A14: 11 | B14: Map economics fully hardcoded | C14: All KPI badges, economics panels, and CAPEX bar charts are hardcoded HTML strings. Any model change requires manual map edit. | D14: Documented. Map should be updated to read from a JSON export or the model directly.
A15: 12 | B15: Sector equipment assumption mislabeled | C15: Assumptions showed "Sector Equipment (Tarana G2 BN + BH)" at $50K. Actual G2 BN is $21K. $50K was never used anyway. | D15: Replaced with actual Tarana pricing: G2 BN $21K/sector, P2P BH $11,634/sector, per-site accessories $1,446.
A16: 13 | B16: No OPEX escalator | C16: Fixed costs assumed flat for 5 years. Tower leases, power, labor all inflate. | D16: Added 3% annual escalator on fixed OPEX items.
